Workbook
Name Slicer_Plant: #N/A
Name Slicer_Region: #N/A

Sheet Dashboard
B2: PANB SUMMARY OF COMPLIANCE

Sheet Pivot
A3: Sum of Active Applicable License / Certification | B3: Sum of Total Applicable License / Certification
A4: 391 | B4: 694
B10: =GETPIVOTDATA("[Measures].[Sum of Active Applicable License / Certification]",$A$3) -> 391 | C10: =GETPIVOTDATA("[Measures].[Sum of Total Applicable License / Certification]",$A$3) -> 694 | J10: =GETPIVOTDATA("[Measures].[Sum of Updated Reportorial]",$J$16) -> 22 | K10: =GETPIVOTDATA("[Measures].[Sum of Total Applicable Reportorials]",$J$16) -> 1062
C11: =B10/C10 -> 0.56340058 | D11: =1-C11 -> 0.43659942 | K11: =J10/K10 -> 0.020715631 | L11: =1-K11 -> 0.97928437
J16: Sum of Updated Reportorial | K16: Sum of Total Applicable Reportorials
J17: 22 | K17: 1062

Sheet SUMMARY-Permits
B2: Region | C2: Plant | D2: LGU Business Permit | E2: LGU Sanitary Permit (CHO/MHO) | F2: LGU Environmental Permit (CENRO/MENRO) | G2: LGU Certificate of Registration and Accreditation as Slaughterhouse | H2: LGU Permit to Operate of Piggeries. Poultry Farms, and Other Livestock Raising Entities | I2: LGU Certificate of Potability | J2: DLE Registration of Establishment (DOLE Rule 1020) | K2: DLE Annual Inspection Certificate (Mechanical, Electrical, Occupancy) | L2: DLE Mechanical Permit to Operate (PTO) (Boilers) | M2: DLE Mechanical Permit to Operate (PTO) (Pressure Vessels) | N2: DLE Mechanical Permit to Operate (PTO) (Internal Combustion Engines) | O2: DOLE Permit to Operate (Electrical Installation) | P2: DLE Mechanical Permit to Operate (PTO) (Elevators) | Q2: DLE Mechanical Permit to Operate (PTO) (Cranes and Hoists) | R2: DLE Mechanical Permit to Operate (PTO) (Power Piping) | S2: BFP Fire Safety Inspection Certificate (FSIC) | T2: BFP Fire Safety Clearance for Storage of Flammable/Combustible Liquids | U2: DENR Environmental Compliance Certificate (ECC) | V2: DENR Certificate of Non-Coverage (CNC) | W2: DENR Hazardous Waste Generator's ID Registration | X2: DENR Permit to Operate (Air Pollution Source Installation) | Y2: DENR Permit to Operate (Air Pollution Source Installation No. 2) | Z2: DENR Permit to Operate (Air Pollution Source Installation No. 3) | AA2: DENR Discharge Permit | AB2: DENR Wastewater Discharge Permit No. 2 | AC2: DENR Wastewater Discharge Permit No. 3 | AD2: DENR Wastewater Discharge Exemption Memo | AE2: DENR PCO Accreditation | AF2: DENR Managing Head Accreditation | AG2: DENR Controlled Chemical Order (CCO) Registration | AH2: DENR CCO Importation Clearance | AI2: DENR PCL Compliance Certificate | AJ2: DENR PCL Compliance Certificate Exemption | AK2: DENR PMPIN Compliance Certificate | AL2: DENR SQI Permit | AM2: DENR Polymer Exemption | AN2: BAI Certificate of Feed Establishment Registration (Manufacturer) | AO2: BAI Certificate of Feed Establishment Registration (Importer) | AP2: BAI Certificate of Feed Establishment Registration (Exporter) | AQ2: BAI Certificate of Feed Establishment Registration (Trader)\\ | AR2: BAI Certificate of Feed Establishment Registration (Repacker) | AS2: BAI Certificate of Feed Ingredient Manufacturer | AT2: BAI Certificate of Laboratory Accreditation | AU2: BAI AWA License to Operate - Internal Hatchery (Chicken) | AV2: BAI Animal Disease Monitoring Compliance Certificate | AW2: NWRB Water Extraction Permit (Deepwell No. 1) | AX2: NWRB Water Extraction Permit (Deepwell No. 2) | AY2: NWRB Water Extraction Permit (Deepwell No. 3) | AZ2: NWRB Water Extraction Permit (Deepwell No. 4) | BA2: NWRB Water Extraction Permit (Deepwell No. 5) | BB2: NWRB Water Extraction Permit (Deepwell No. 6) | BC2: FDA License to Operate | BD2: NMIS License to Operate - Dressing / Fabrication of Poultry for Domestic Trade | BE2: NMIS License to Operate - Cold Storage Warehouse (CSW) | BF2: HACCP Certification - Fresh Chilled and Frozen Whole Dressed Chicken | BG2: HACCP Certification - Fresh Chilled and Frozen Unmarinated Deboned Meat | BH2: HACCP Certification - Fresh Chilled and Frozen Unmarinated Bone-in Cut-ups | BI2: HACCP Certification - Fresh Chilled and Frozen Giblets | BJ2: DOE Coal End-User Registration Certificate | BK2: ERC Certificate of Compliance | BL2: PNP Purchaser’s License (For Controlled Substances) | BM2: PDEA License to Handle Controlled Substances | BN2: PDEA License to Handle Precurssors and Essential Chemicals | BP2: Total Applicable License / Certification | BQ2: Active Applicable License / Certification | BR2: %Active
B3: North Luzon | C3: BMP Pangasinan | D3: =IF('BMP Pangasinan'!$H$6="n/a","na",IF('BMP Pangasinan'!$H$6="Active","✓","x")) -> ✓ | E3: =IF('BMP Pangasinan'!$H$7="n/a","na",IF('BMP Pangasinan'!$H$7="Active","✓","x")) -> ✓ | F3: =IF('BMP Pangasinan'!$H$8="n/a","na",IF('BMP Pangasinan'!$H$8="Active","✓","x")) -> ✓ | G3: =IF('BMP Pangasinan'!$H$9="n/a","na",IF('BMP Pangasinan'!$H$9="Active","✓","x")) -> na | H3: =IF('BMP Pangasinan'!$H$10="n/a","na",IF('BMP Pangasinan'!$H$10="Active","✓","x")) -> na | I3: =IF('BMP Pangasinan'!$H$11="n/a","na",IF('BMP Pangasinan'!$H$11="Active","✓","x")) -> na | J3: =IF('BMP Pangasinan'!$H$12="n/a","na",IF('BMP Pangasinan'!$H$12="Active","✓","x")) -> ✓ | K3: =IF('BMP Pangasinan'!$H$13="n/a","na",IF('BMP Pangasinan'!$H$13="Active","✓","x")) -> ✓ | L3: =IF('BMP Pangasinan'!$H$14="n/a","na",IF('BMP Pangasinan'!$H$14="Active","✓","x")) -> ✓ | M3: =IF('BMP Pangasinan'!$H$16="n/a","na",IF('BMP Pangasinan'!$H$16="Active","✓","x")) -> ✓ | N3: =IF('BMP Pangasinan'!$H$17="n/a","na",IF('BMP Pangasinan'!$H$17="Active","✓","x")) -> ✓ | O3: =IF('BMP Pangasinan'!$H$18="n/a","na",IF('BMP Pangasinan'!$H$18="Active","✓","x")) -> ✓ | P3: =IF('BMP Pangasinan'!$H$19="n/a","na",IF('BMP Pangasinan'!$H$19="Active","✓","x")) -> ✓ | Q3: =IF('BMP Pangasinan'!$H$20="n/a","na",IF('BMP Pangasinan'!$H$20="Active","✓","x")) -> na | R3: =IF('BMP Pangasinan'!$H$21="n/a","na",IF('BMP Pangasinan'!$H$21="Active","✓","x")) -> ✓ | S3: =IF('BMP Pangasinan'!$H$22="n/a","na",IF('BMP Pangasinan'!$H$22="Active","✓","x")) -> ✓ | T3: =IF('BMP Pangasinan'!$H$23="n/a","na",IF('BMP Pangasinan'!$H$23="Active","✓","x")) -> ✓ | U3: =IF('BMP Pangasinan'!$H$24="n/a","na",IF('BMP Pangasinan'!$H$24="Active","✓","x")) -> ✓ | V3: =IF('BMP Pangasinan'!$H$25="n/a","na",IF('BMP Pangasinan'!$H$25="Active","✓","x")) -> na | W3: =IF('BMP Pangasinan'!$H$26="n/a","na",IF('BMP Pangasinan'!$H$26="Active","✓","x")) -> ✓ | X3: =IF('BMP Pangasinan'!$H$27="n/a","na",IF('BMP Pangasinan'!$H$27="Active","✓","x")) -> ✓ | Y3: =IF('BMP Pangasinan'!$H$28="n/a","na",IF('BMP Pangasinan'!$H$28="Active","✓","x")) -> na | Z3: =IF('BMP Pangasinan'!$H$29="n/a","na",IF('BMP Pangasinan'!$H$29="Active","✓","x")) -> na | AA3: =IF('BMP Pangasinan'!$H$30="n/a","na",IF('BMP Pangasinan'!$H$30="Active","✓","x")) -> ✓ | AB3: =IF('BMP Pangasinan'!$H$31="n/a","na",IF('BMP Pangasinan'!$H$31="Active","✓","x")) -> na | AC3: =IF('BMP Pangasinan'!$H$32="n/a","na",IF('BMP Pangasinan'!$H$32="Active","✓","x")) -> na | AD3: =IF('BMP Pangasinan'!$H$33="n/a","na",IF('BMP Pangasinan'!$H$33="Active","✓","x")) -> na | AE3: =IF('BMP Pangasinan'!$H$34="n/a","na",IF('BMP Pangasinan'!$H$34="Active","✓","x")) -> ✓ | AF3: =IF('BMP Pangasinan'!$H$35="n/a","na",IF('BMP Pangasinan'!$H$35="Active","✓","x")) -> ✓ | AG3: =IF('BMP Pangasinan'!$H$36="n/a","na",IF('BMP Pangasinan'!$H$36="Active","✓","x")) -> ✓ | AH3: =IF('BMP Pangasinan'!$H$37="n/a","na",IF('BMP Pangasinan'!$H$37="Active","✓","x")) -> na | AI3: =IF('BMP Pangasinan'!$H$38="n/a","na",IF('BMP Pangasinan'!$H$38="Active","✓","x")) -> na | AJ3: =IF('BMP Pangasinan'!$H$39="n/a","na",IF('BMP Pangasinan'!$H$39="Active","✓","x")) -> ✓ | AK3: =IF('BMP Pangasinan'!$H$40="n/a","na",IF('BMP Pangasinan'!$H$40="Active","✓","x")) -> na | AL3: =IF('BMP Pangasinan'!$H$41="n/a","na",IF('BMP Pangasinan'!$H$41="Active","✓","x")) -> na | AM3: =IF('BMP Pangasinan'!$H$42="n/a","na",IF('BMP Pangasinan'!$H$42="Active","✓","x")) -> na | AN3: =IF('BMP Pangasinan'!$H$43="n/a","na",IF('BMP Pangasinan'!$H$43="Active","✓","x")) -> ✓ | AO3: =IF('BMP Pangasinan'!$H$44="n/a","na",IF('BMP Pangasinan'!$H$44="Active","✓","x")) -> ✓ | AP3: =IF('BMP Pangasinan'!$H$45="n/a","na",IF('BMP Pangasinan'!$H$45="Active","✓","x")) -> ✓ | AQ3: =IF('BMP Pangasinan'!$H$46="n/a","na",IF('BMP Pangasinan'!$H$46="Active","✓","x")) -> ✓ | AR3: =IF('BMP Pangasinan'!$H$47="n/a","na",IF('BMP Pangasinan'!$H$47="Active","✓","x")) -> na | AS3: =IF('BMP Pangasinan'!$H$48="n/a","na",IF('BMP Pangasinan'!$H$48="Active","✓","x")) -> na | AT3: =IF('BMP Pangasinan'!$H$49="n/a","na",IF('BMP Pangasinan'!$H$49="Active","✓","x")) -> na | AU3: =IF('BMP Pangasinan'!$H$50="n/a","na",IF('BMP Pangasinan'!$H$50="Active","✓","x")) -> na | AV3: =IF('BMP Pangasinan'!$H$51="n/a","na",IF('BMP Pangasinan'!$H$51="Active","✓","x")) -> na | AW3: =IF('BMP Pangasinan'!$H$52="n/a","na",IF('BMP Pangasinan'!$H$52="Active","✓","x")) -> ✓ | AX3: =IF('BMP Pangasinan'!$H$53="n/a","na",IF('BMP Pangasinan'!$H$53="Active","✓","x")) -> na | AY3: =IF('BMP Pangasinan'!$H$54="n/a","na",IF('BMP Pangasinan'!$H$54="Active","✓","x")) -> na | AZ3: =IF('BMP Pangasinan'!$H$55="n/a","na",IF('BMP Pangasinan'!$H$55="Active","✓","x")) -> na | BA3: =IF('BMP Pangasinan'!$H$56="n/a","na",IF('BMP Pangasinan'!$H$56="Active","✓","x")) -> na | BB3: =IF('BMP Pangasinan'!$H$57="n/a","na",IF('BMP Pangasinan'!$H$57="Active","✓","x")) -> na | BC3: =IF('BMP Pangasinan'!$H$58="n/a","na",IF('BMP Pangasinan'!$H$58="Active","✓","x")) -> na | BD3: =IF('BMP Pangasinan'!$H$59="n/a","na",IF('BMP Pangasinan'!$H$59="Active","✓","x")) -> na | BE3: =IF('BMP Pangasinan'!$H$60="n/a","na",IF('BMP Pangasinan'!$H$60="Active","✓","x")) -> na | BF3: =IF('BMP Pangasinan'!$H$61="n/a","na",IF('BMP Pangasinan'!$H$61="Active","✓","x")) -> na | BG3: =IF('BMP Pangasinan'!$H$62="n/a","na",IF('BMP Pangasinan'!$H$62="Active","✓","x")) -> na | BH3: =IF('BMP Pangasinan'!$H$63="n/a","na",IF('BMP Pangasinan'!$H$63="Active","✓","x")) -> na | BI3: =IF('BMP Pangasinan'!$H$64="n/a","na",IF('BMP Pangasinan'!$H$64="Active","✓","x")) -> na | BJ3: =IF('BMP Pangasinan'!$H$65="n/a","na",IF('BMP Pangasinan'!$H$65="Active","✓","x")) -> na | BK3: =IF('BMP Pangasinan'!$H$66="n/a","na",IF('BMP Pangasinan'!$H$66="Active","✓","x")) -> na | BL3: =IF('BMP Pangasinan'!$H$67="n/a","na",IF('BMP Pangasinan'!$H$67="Active","✓","x")) -> x | BM3: =IF('BMP Pangasinan'!$H$68="n/a","na",IF('BMP Pangasinan'!$H$68="Active","✓","x")) -> na | BN3: =IF('BMP Pangasinan'!$H$69="n/a","na",IF('BMP Pangasinan'!$H$69="Active","✓","x")) -> x | BP3: =COUNTIF(D3:BN3,"*")-COUNTIF(D3:BN3,"NA") -> 28 | BQ3: =COUNTIF(D3:BN3,"✓") -> 26 | BR3: =IFERROR(BQ3/BP3,0) -> 0.92857143
B4: North Luzon | C4: BMP Isabela | D4: =IF('BMP Isabela'!$H$6="n/a","na",IF('BMP Isabela'!$H$6="Active","✓","x")) -> ✓ | E4: =IF('BMP Isabela'!$H$7="n/a","na",IF('BMP Isabela'!$H$7="Active","✓","x")) -> ✓ | F4: =IF('BMP Isabela'!$H$8="n/a","na",IF('BMP Isabela'!$H$8="Active","✓","x")) -> na | G4: =IF('BMP Isabela'!$H$9="n/a","na",IF('BMP Isabela'!$H$9="Active","✓","x")) -> na | H4: =IF('BMP Isabela'!$H$10="n/a","na",IF('BMP Isabela'!$H$10="Active","✓","x")) -> na | I4: =IF('BMP Isabela'!$H$11="n/a","na",IF('BMP Isabela'!$H$11="Active","✓","x")) -> na | J4: =IF('BMP Isabela'!$H$12="n/a","na",IF('BMP Isabela'!$H$12="Active","✓","x")) -> ✓ | K4: =IF('BMP Isabela'!$H$13="n/a","na",IF('BMP Isabela'!$H$13="Active","✓","x")) -> ✓ | L4: =IF('BMP Isabela'!$H$14="n/a","na",IF('BMP Isabela'!$H$14="Active","✓","x")) -> ✓ | M4: =IF('BMP Isabela'!$H$15="n/a","na",IF('BMP Isabela'!$H$15="Active","✓","x")) -> ✓ | N4: =IF('BMP Isabela'!$H$16="n/a","na",IF('BMP Isabela'!$H$16="Active","✓","x")) -> ✓ | O4: =IF('BMP Isabela'!$H$17="n/a","na",IF('BMP Isabela'!$H$17="Active","✓","x")) -> na | P4: =IF('BMP Isabela'!$H$18="n/a","na",IF('BMP Isabela'!$H$18="Active","✓","x")) -> ✓ | Q4: =IF('BMP Isabela'!$H$19="n/a","na",IF('BMP Isabela'!$H$19="Active","✓","x")) -> ✓ | R4: =IF('BMP Isabela'!$H$20="n/a","na",IF('BMP Isabela'!$H$20="Active","✓","x")) -> ✓ | S4: =IF('BMP Isabela'!$H$21="n/a","na",IF('BMP Isabela'!$H$21="Active","✓","x")) -> ✓ | T4: =IF('BMP Isabela'!$H$22="n/a","na",IF('BMP Isabela'!$H$22="Active","✓","x")) -> ✓ | U4: =IF('BMP Isabela'!$H$23="n/a","na",IF('BMP Isabela'!$H$23="Active","✓","x")) -> ✓ | V4: =IF('BMP Isabela'!$H$24="n/a","na",IF('BMP Isabela'!$H$24="Active","✓","x")) -> na | W4: =IF('BMP Isabela'!$H$25="n/a","na",IF('BMP Isabela'!$H$25="Active","✓","x")) -> ✓ | X4: =IF('BMP Isabela'!$H$26="n/a","na",IF('BMP Isabela'!$H$26="Active","✓","x")) -> ✓ | Y4: =IF('BMP Isabela'!$H$27="n/a","na",IF('BMP Isabela'!$H$27="Active","✓","x")) -> na | Z4: =IF('BMP Isabela'!$H$28="n/a","na",IF('BMP Isabela'!$H$28="Active","✓","x")) -> na | AA4: =IF('BMP Isabela'!$H$29="n/a","na",IF('BMP Isabela'!$H$29="Active","✓","x")) -> ✓ | AB4: =IF('BMP Isabela'!$H$30="n/a","na",IF('BMP Isabela'!$H$30="Active","✓","x")) -> na | AC4: =IF('BMP Isabela'!$H$31="n/a","na",IF('BMP Isabela'!$H$31="Active","✓","x")) -> na | AD4: =IF('BMP Isabela'!$H$32="n/a","na",IF('BMP Isabela'!$H$32="Active","✓","x")) -> na | AE4: =IF('BMP Isabela'!$H$33="n/a","na",IF('BMP Isabela'!$H$33="Active","✓","x")) -> ✓ | AF4: =IF('BMP Isabela'!$H$34="n/a","na",IF('BMP Isabela'!$H$34="Active","✓","x")) -> ✓ | AG4: =IF('BMP Isabela'!$H$35="n/a","na",IF('BMP Isabela'!$H$35="Active","✓","x")) -> na | AH4: =IF('BMP Isabela'!$H$36="n/a","na",IF('BMP Isabela'!$H$36="Active","✓","x")) -> na | AI4: =IF('BMP Isabela'!$H$37="n/a","na",IF('BMP Isabela'!$H$37="Active","✓","x")) -> na | AJ4: =IF('BMP Isabela'!$H$38="n/a","na",IF('BMP Isabela'!$H$38="Active","✓","x")) -> na | AK4: =IF('BMP Isabela'!$H$39="n/a","na",IF('BMP Isabela'!$H$39="Active","✓","x")) -> na | AL4: =IF('BMP Isabela'!$H$40="n/a","na",IF('BMP Isabela'!$H$40="Active","✓","x")) -> na | AM4: =IF('BMP Isabela'!$H$41="n/a","na",IF('BMP Isabela'!$H$41="Active","✓","x")) -> na | AN4: =IF('BMP Isabela'!$H$42="n/a","na",IF('BMP Isabela'!$H$42="Active","✓","x")) -> ✓ | AO4: =IF('BMP Isabela'!$H$43="n/a","na",IF('BMP Isabela'!$H$43="Active","✓","x")) -> na | AP4: =IF('BMP Isabela'!$H$44="n/a","na",IF('BMP Isabela'!$H$44="Active","✓","x")) -> na | AQ4: =IF('BMP Isabela'!$H$45="n/a","na",IF('BMP Isabela'!$H$45="Active","✓","x")) -> na | AR4: =IF('BMP Isabela'!$H$46="n/a","na",IF('BMP Isabela'!$H$46="Active","✓","x")) -> na | AS4: =IF('BMP Isabela'!$H$47="n/a","na",IF('BMP Isabela'!$H$47="Active","✓","x")) -> na | AT4: =IF('BMP Isabela'!$H$48="n/a","na",IF('BMP Isabela'!$H$48="Active","✓","x")) -> na | AU4: =IF('BMP Isabela'!$H$49="n/a","na",IF('BMP Isabela'!$H$49="Active","✓","x")) -> na | AV4: =IF('BMP Isabela'!$H$50="n/a","na",IF('BMP Isabela'!$H$50="Active","✓","x")) -> na | AW4: =IF('BMP Isabela'!$H$51="n/a","na",IF('BMP Isabela'!$H$51="Active","✓","x")) -> ✓ | AX4: =IF('BMP Isabela'!$H$52="n/a","na",IF('BMP Isabela'!$H$52="Active","✓","x")) -> ✓ | AY4: =IF('BMP Isabela'!$H$53="n/a","na",IF('BMP Isabela'!$H$53="Active","✓","x")) -> na | AZ4: =IF('BMP Isabela'!$H$54="n/a","na",IF('BMP Isabela'!$H$54="Active","✓","x")) -> na | BA4: =IF('BMP Isabela'!$H$55="n/a","na",IF('BMP Isabela'!$H$55="Active","✓","x")) -> na | BB4: =IF('BMP Isabela'!$H$56="n/a","na",IF('BMP Isabela'!$H$56="Active","✓","x")) -> na | BC4: =IF('BMP Isabela'!$H$57="n/a","na",IF('BMP Isabela'!$H$57="Active","✓","x")) -> na | BD4: =IF('BMP Isabela'!$H$58="n/a","na",IF('BMP Isabela'!$H$58="Active","✓","x")) -> na | BE4: =IF('BMP Isabela'!$H$59="n/a","na",IF('BMP Isabela'!$H$59="Active","✓","x")) -> na | BF4: =IF('BMP Isabela'!$H$60="n/a","na",IF('BMP Isabela'!$H$60="Active","✓","x")) -> na | BG4: =IF('BMP Isabela'!$H$61="n/a","na",IF('BMP Isabela'!$H$61="Active","✓","x")) -> na | BH4: =IF('BMP Isabela'!$H$62="n/a","na",IF('BMP Isabela'!$H$62="Active","✓","x")) -> na | BI4: =IF('BMP Isabela'!$H$63="n/a","na",IF('BMP Isabela'!$H$63="Active","✓","x")) -> na | BJ4: =IF('BMP Isabela'!$H$64="n/a","na",IF('BMP Isabela'!$H$64="Active","✓","x")) -> ✓ | BK4: =IF('BMP Isabela'!$H$65="n/a","na",IF('BMP Isabela'!$H$65="Active","✓","x")) -> na | BL4: =IF('BMP Isabela'!$H$66="n/a","na",IF('BMP Isabela'!$H$66="Active","✓","x")) -> ✓ | BM4: =IF('BMP Isabela'!$H$67="n/a","na",IF('BMP Isabela'!$H$67="Active","✓","x")) -> na | BN4: =IF('BMP Isabela'!$H$68="n/a","na",IF('BMP Isabela'!$H$68="Active","✓","x")) -> ✓ | BP4: =COUNTIF(D4:BN4,"*")-COUNTIF(D4:BN4,"NA") -> 24 | BQ4: =COUNTIF(D4:BN4,"✓") -> 24 | BR4: =IFERROR(BQ4/BP4,0) -> 1
B5: North Luzon | C5: BMP Bataan 1 | D5: =IF('BMP Bataan 1'!$H$6="n/a","na",IF('BMP Bataan 1'!$H$6="Active","✓","x")) -> ✓ | E5: =IF('BMP Bataan 1'!$H$7="n/a","na",IF('BMP Bataan 1'!$H$7="Active","✓","x")) -> ✓ | F5: =IF('BMP Bataan 1'!$H$8="n/a","na",IF('BMP Bataan 1'!$H$8="Active","✓","x")) -> ✓ | G5: =IF('BMP Bataan 1'!$H$9="n/a","na",IF('BMP Bataan 1'!$H$9="Active","✓","x")) -> na | H5: =IF('BMP Bataan 1'!$H$10="n/a","na",IF('BMP Bataan 1'!$H$10="Active","✓","x")) -> na | I5: =IF('BMP Bataan 1'!$H$11="n/a","na",IF('BMP Bataan 1'!$H$11="Active","✓","x")) -> na | J5: =IF('BMP Bataan 1'!$H$12="n/a","na",IF('BMP Bataan 1'!$H$12="Active","✓","x")) -> ✓ | K5: =IF('BMP Bataan 1'!$H$13="n/a","na",IF('BMP Bataan 1'!$H$13="Active","✓","x")) -> ✓ | L5: =IF('BMP Bataan 1'!$H$14="n/a","na",IF('BMP Bataan 1'!$H$14="Active","✓","x")) -> ✓ | M5: =IF('BMP Bataan 1'!$H$15="n/a","na",IF('BMP Bataan 1'!$H$15="Active","✓","x")) -> ✓ | N5: =IF('BMP Bataan 1'!$H$16="n/a","na",IF('BMP Bataan 1'!$H$16="Active","✓","x")) -> ✓ | O5: =IF('BMP Bataan 1'!$H$17="n/a","na",IF('BMP Bataan 1'!$H$17="Active","✓","x")) -> ✓ | P5: =IF('BMP Bataan 1'!$H$18="n/a","na",IF('BMP Bataan 1'!$H$18="Active","✓","x")) -> na | Q5: =IF('BMP Bataan 1'!$H$19="n/a","na",IF('BMP Bataan 1'!$H$19="Active","✓","x")) -> ✓ | R5: =IF('BMP Bataan 1'!$H$20="n/a","na",IF('BMP Bataan 1'!$H$20="Active","✓","x")) -> ✓ | S5: =IF('BMP Bataan 1'!$H$21="n/a","na",IF('BMP Bataan 1'!$H$21="Active","✓","x")) -> ✓ | T5: =IF('BMP Bataan 1'!$H$22="n/a","na",IF('BMP Bataan 1'!$H$22="Active","✓","x")) -> ✓ | U5: =IF('BMP Bataan 1'!$H$23="n/a","na",IF('BMP Bataan 1'!$H$23="Active","✓","x")) -> ✓ | V5: =IF('BMP Bataan 1'!$H$24="n/a","na",IF('BMP Bataan 1'!$H$24="Active","✓","x")) -> na | W5: =IF('BMP Bataan 1'!$H$25="n/a","na",IF('BMP Bataan 1'!$H$25="Active","✓","x")) -> ✓ | X5: =IF('BMP Bataan 1'!$H$26="n/a","na",IF('BMP Bataan 1'!$H$26="Active","✓","x")) -> ✓ | Y5: =IF('BMP Bataan 1'!$H$27="n/a","na",IF('BMP Bataan 1'!$H$27="Active","✓","x")) -> na | Z5: =IF('BMP Bataan 1'!$H$28="n/a","na",IF('BMP Bataan 1'!$H$28="Active","✓","x")) -> na | AA5: =IF('BMP Bataan 1'!$H$29="n/a","na",IF('BMP Bataan 1'!$H$29="Active","✓","x")) -> na | AB5: =IF('BMP Bataan 1'!$H$30="n/a","na",IF('BMP Bataan 1'!$H$30="Active","✓","x")) -> na | AC5: =IF('BMP Bataan 1'!$H$31="n/a","na",IF('BMP Bataan 1'!$H$31="Active","✓","x")) -> na | AD5: =IF('BMP Bataan 1'!$H$32="n/a","na",IF('BMP Bataan 1'!$H$32="Active","✓","x")) -> ✓ | AE5: =IF('BMP Bataan 1'!$H$33="n/a","na",IF('BMP Bataan 1'!$H$33="Active","✓","x")) -> ✓ | AF5: =IF('BMP Bataan 1'!$H$34="n/a","na",IF('BMP Bataan 1'!$H$34="Active","✓","x")) -> ✓ | AG5: =IF('BMP Bataan 1'!$H$35="n/a","na",IF('BMP Bataan 1'!$H$35="Active","✓","x")) -> ✓ | AH5: =IF('BMP Bataan 1'!$H$36="n/a","na",IF('BMP Bataan 1'!$H$36="Active","✓","x")) -> na | AI5: =IF('BMP Bataan 1'!$H$37="n/a","na",IF('BMP Bataan 1'!$H$37="Active","✓","x")) -> na | AJ5: =IF('BMP Bataan 1'!$H$38="n/a","na",IF('BMP Bataan 1'!$H$38="Active","✓","x")) -> ✓ | AK5: =IF('BMP Bataan 1'!$H$39="n/a","na",IF('BMP Bataan 1'!$H$39="Active","✓","x")) -> na | AL5: =IF('BMP Bataan 1'!$H$40="n/a","na",IF('BMP Bataan 1'!$H$40="Active","✓","x")) -> na | AM5: =IF('BMP Bataan 1'!$H$41="n/a","na",IF('BMP Bataan 1'!$H$41="Active","✓","x")) -> na | AN5: =IF('BMP Bataan 1'!$H$42="n/a","na",IF('BMP Bataan 1'!$H$42="Active","✓","x")) -> ✓ | AO5: =IF('BMP Bataan 1'!$H$43="n/a","na",IF('BMP Bataan 1'!$H$43="Active","✓","x")) -> na | AP5: =IF('BMP Bataan 1'!$H$44="n/a","na",IF('BMP Bataan 1'!$H$44="Active","✓","x")) -> na | AQ5: =IF('BMP Bataan 1'!$H$45="n/a","na",IF('BMP Bataan 1'!$H$45="Active","✓","x")) -> na | AR5: =IF('BMP Bataan 1'!$H$46="n/a","na",IF('BMP Bataan 1'!$H$46="Active","✓","x")) -> na | AS5: =IF('BMP Bataan 1'!$H$47="n/a","na",IF('BMP Bataan 1'!$H$47="Active","✓","x")) -> na | AT5: =IF('BMP Bataan 1'!$H$48="n/a","na",IF('BMP Bataan 1'!$H$48="Active","✓","x")) -> x | AU5: =IF('BMP Bataan 1'!$H$49="n/a","na",IF('BMP Bataan 1'!$H$49="Active","✓","x")) -> na | AV5: =IF('BMP Bataan 1'!$H$50="n/a","na",IF('BMP Bataan 1'!$H$50="Active","✓","x")) -> na | AW5: =IF('BMP Bataan 1'!$H$51="n/a","na",IF('BMP Bataan 1'!$H$51="Active","✓","x")) -> na | AX5: =IF('BMP Bataan 1'!$H$52="n/a","na",IF('BMP Bataan 1'!$H$52="Active","✓","x")) -> na | AY5: =IF('BMP Bataan 1'!$H$53="n/a","na",IF('BMP Bataan 1'!$H$53="Active","✓","x")) -> na | AZ5: =IF('BMP Bataan 1'!$H$54="n/a","na",IF('BMP Bataan 1'!$H$54="Active","✓","x")) -> na | BA5: =IF('BMP Bataan 1'!$H$55="n/a","na",IF('BMP Bataan 1'!$H$55="Active","✓","x")) -> na | BB5: =IF('BMP Bataan 1'!$H$56="n/a","na",IF('BMP Bataan 1'!$H$56="Active","✓","x")) -> na | BC5: =IF('BMP Bataan 1'!$H$57="n/a","na",IF('BMP Bataan 1'!$H$57="Active","✓","x")) -> na | BD5: =IF('BMP Bataan 1'!$H$58="n/a","na",IF('BMP Bataan 1'!$H$58="Active","✓","x")) -> na | BE5: =IF('BMP Bataan 1'!$H$59="n/a","na",IF('BMP Bataan 1'!$H$59="Active","✓","x")) -> na | BF5: =IF('BMP Bataan 1'!$H$60="n/a","na",IF('BMP Bataan 1'!$H$60="Active","✓","x")) -> na | BG5: =IF('BMP Bataan 1'!$H$61="n/a","na",IF('BMP Bataan 1'!$H$61="Active","✓","x")) -> na | BH5: =IF('BMP Bataan 1'!$H$62="n/a","na",IF('BMP Bataan 1'!$H$62="Active","✓","x")) -> na | BI5: =IF('BMP Bataan 1'!$H$63="n/a","na",IF('BMP Bataan 1'!$H$63="Active","✓","x")) -> na | BJ5: =IF('BMP Bataan 1'!$H$64="n/a","na",IF('BMP Bataan 1'!$H$64="Active","✓","x")) -> na | BK5: =IF('BMP Bataan 1'!$H$65="n/a","na",IF('BMP Bataan 1'!$H$65="Active","✓","x")) -> x | BL5: =IF('BMP Bataan 1'!$H$66="n/a","na",IF('BMP Bataan 1'!$H$66="Active","✓","x")) -> ✓ | BM5: =IF('BMP Bataan 1'!$H$67="n/a","na",IF('BMP Bataan 1'!$H$67="Active","✓","x")) -> ✓ | BN5: =IF('BMP Bataan 1'!$H$68="n/a","na",IF('BMP Bataan 1'!$H$68="Active","✓","x")) -> ✓ | BP5: =COUNTIF(D5:BN5,"*")-COUNTIF(D5:BN5,"NA") -> 27 | BQ5: =COUNTIF(D5:BN5,"✓") -> 25 | BR5: =IFERROR(BQ5/BP5,0) -> 0.92592593
B6: North Luzon | C6: BMP Bataan 2 | D6: =IF('BMP Bataan 2'!$H$6="n/a","na",IF('BMP Bataan 2'!$H$6="Active","✓","x")) -> ✓ | E6: =IF('BMP Bataan 2'!$H$7="n/a","na",IF('BMP Bataan 2'!$H$7="Active","✓","x")) -> ✓ | F6: =IF('BMP Bataan 2'!$H$8="n/a","na",IF('BMP Bataan 2'!$H$8="Active","✓","x")) -> ✓ | G6: =IF('BMP Bataan 2'!$H$9="n/a","na",IF('BMP Bataan 2'!$H$9="Active","✓","x")) -> na | H6: =IF('BMP Bataan 2'!$H$10="n/a","na",IF('BMP Bataan 2'!$H$10="Active","✓","x")) -> na | I6: =IF('BMP Bataan 2'!$H$11="n/a","na",IF('BMP Bataan 2'!$H$11="Active","✓","x")) -> na | J6: =IF('BMP Bataan 2'!$H$12="n/a","na",IF('BMP Bataan 2'!$H$12="Active","✓","x")) -> ✓ | K6: =IF('BMP Bataan 2'!$H$13="n/a","na",IF('BMP Bataan 2'!$H$13="Active","✓","x")) -> x | L6: =IF('BMP Bataan 2'!$H$14="n/a","na",IF('BMP Bataan 2'!$H$14="Active","✓","x")) -> ✓ | M6: =IF('BMP Bataan 2'!$H$15="n/a","na",IF('BMP Bataan 2'!$H$15="Active","✓","x")) -> ✓ | N6: =IF('BMP Bataan 2'!$H$16="n/a","na",IF('BMP Bataan 2'!$H$16="Active","✓","x")) -> ✓ | O6: =IF('BMP Bataan 2'!$H$17="n/a","na",IF('BMP Bataan 2'!$H$17="Active","✓","x")) -> na | P6: =IF('BMP Bataan 2'!$H$18="n/a","na",IF('BMP Bataan 2'!$H$18="Active","✓","x")) -> ✓ | Q6: =IF('BMP Bataan 2'!$H$19="n/a","na",IF('BMP Bataan 2'!$H$19="Active","✓","x")) -> ✓ | R6: =IF('BMP Bataan 2'!$H$20="n/a","na",IF('BMP Bataan 2'!$H$20="Active","✓","x")) -> ✓ | S6: =IF('BMP Bataan 2'!$H$21="n/a","na",IF('BMP Bataan 2'!$H$21="Active","✓","x")) -> ✓ | T6: =IF('BMP Bataan 2'!$H$22="n/a","na",IF('BMP Bataan 2'!$H$22="Active","✓","x")) -> ✓ | U6: =IF('BMP Bataan 2'!$H$23="n/a","na",IF('BMP Bataan 2'!$H$23="Active","✓","x")) -> ✓ | V6: =IF('BMP Bataan 2'!$H$24="n/a","na",IF('BMP Bataan 2'!$H$24="Active","✓","x")) -> na | W6: =IF('BMP Bataan 2'!$H$25="n/a","na",IF('BMP Bataan 2'!$H$25="Active","✓","x")) -> ✓ | X6: =IF('BMP Bataan 2'!$H$26="n/a","na",IF('BMP Bataan 2'!$H$26="Active","✓","x")) -> ✓ | Y6: =IF('BMP Bataan 2'!$H$27="n/a","na",IF('BMP Bataan 2'!$H$27="Active","✓","x")) -> na | Z6: =IF('BMP Bataan 2'!$H$28="n/a","na",IF('BMP Bataan 2'!$H$28="Active","✓","x")) -> na | AA6: =IF('BMP Bataan 2'!$H$29="n/a","na",IF('BMP Bataan 2'!$H$29="Active","✓","x")) -> na | AB6: =IF('BMP Bataan 2'!$H$30="n/a","na",IF('BMP Bataan 2'!$H$30="Active","✓","x")) -> na | AC6: =IF('BMP Bataan 2'!$H$31="n/a","na",IF('BMP Bataan 2'!$H$31="Active","✓","x")) -> na | AD6: =IF('BMP Bataan 2'!$H$32="n/a","na",IF('BMP Bataan 2'!$H$32="Active","✓","x")) -> ✓ | AE6: =IF('BMP Bataan 2'!$H$33="n/a","na",IF('BMP Bataan 2'!$H$33="Active","✓","x")) -> ✓ | AF6: =IF('BMP Bataan 2'!$H$34="n/a","na",IF('BMP Bataan 2'!$H$34="Active","✓","x")) -> ✓ | AG6: =IF('BMP Bataan 2'!$H$35="n/a","na",IF('BMP Bataan 2'!$H$35="Active","✓","x")) -> na | AH6: =IF('BMP Bataan 2'!$H$36="n/a","na",IF('BMP Bataan 2'!$H$36="Active","✓","x")) -> na | AI6: =IF('BMP Bataan 2'!$H$37="n/a","na",IF('BMP Bataan 2'!$H$37="Active","✓","x")) -> na | AJ6: =IF('BMP Bataan 2'!$H$38="n/a","na",IF('BMP Bataan 2'!$H$38="Active","✓","x")) -> ✓ | AK6: =IF('BMP Bataan 2'!$H$39="n/a","na",IF('BMP Bataan 2'!$H$39="Active","✓","x")) -> na | AL6: =IF('BMP Bataan 2'!$H$40="n/a","na",IF('BMP Bataan 2'!$H$40="Active","✓","x")) -> na | AM6: =IF('BMP Bataan 2'!$H$41="n/a","na",IF('BMP Bataan 2'!$H$41="Active","✓","x")) -> na | AN6: =IF('BMP Bataan 2'!$H$42="n/a","na",IF('BMP Bataan 2'!$H$42="Active","✓","x")) -> ✓ | AO6: =IF('BMP Bataan 2'!$H$43="n/a","na",IF('BMP Bataan 2'!$H$43="Active","✓","x")) -> na | AP6: =IF('BMP Bataan 2'!$H$44="n/a","na",IF('BMP Bataan 2'!$H$44="Active","✓","x")) -> na | AQ6: =IF('BMP Bataan 2'!$H$45="n/a","na",IF('BMP Bataan 2'!$H$45="Active","✓","x")) -> na | AR6: =IF('BMP Bataan 2'!$H$46="n/a","na",IF('BMP Bataan 2'!$H$46="Active","✓","x")) -> na | AS6: =IF('BMP Bataan 2'!$H$47="n/a","na",IF('BMP Bataan 2'!$H$47="Active","✓","x")) -> na | AT6: =IF('BMP Bataan 2'!$H$48="n/a","na",IF('BMP Bataan 2'!$H$48="Active","✓","x")) -> x | AU6: =IF('BMP Bataan 2'!$H$49="n/a","na",IF('BMP Bataan 2'!$H$49="Active","✓","x")) -> na | AV6: =IF('BMP Bataan 2'!$H$50="n/a","na",IF('BMP Bataan 2'!$H$50="Active","✓","x")) -> na | AW6: =IF('BMP Bataan 2'!$H$51="n/a","na",IF('BMP Bataan 2'!$H$51="Active","✓","x")) -> na | AX6: =IF('BMP Bataan 2'!$H$52="n/a","na",IF('BMP Bataan 2'!$H$52="Active","✓","x")) -> na | AY6: =IF('BMP Bataan 2'!$H$53="n/a","na",IF('BMP Bataan 2'!$H$53="Active","✓","x")) -> na | AZ6: =IF('BMP Bataan 2'!$H$54="n/a","na",IF('BMP Bataan 2'!$H$54="Active","✓","x")) -> na | BA6: =IF('BMP Bataan 2'!$H$55="n/a","na",IF('BMP Bataan 2'!$H$55="Active","✓","x")) -> na | BB6: =IF('BMP Bataan 2'!$H$56="n/a","na",IF('BMP Bataan 2'!$H$56="Active","✓","x")) -> na | BC6: =IF('BMP Bataan 2'!$H$57="n/a","na",IF('BMP Bataan 2'!$H$57="Active","✓","x")) -> na | BD6: =IF('BMP Bataan 2'!$H$58="n/a","na",IF('BMP Bataan 2'!$H$58="Active","✓","x")) -> na | BE6: =IF('BMP Bataan 2'!$H$59="n/a","na",IF('BMP Bataan 2'!$H$59="Active","✓","x")) -> na | BF6: =IF('BMP Bataan 2'!$H$60="n/a","na",IF('BMP Bataan 2'!$H$60="Active","✓","x")) -> na | BG6: =IF('BMP Bataan 2'!$H$61="n/a","na",IF('BMP Bataan 2'!$H$61="Active","✓","x")) -> na | BH6: =IF('BMP Bataan 2'!$H$62="n/a","na",IF('BMP Bataan 2'!$H$62="Active","✓","x")) -> na | BI6: =IF('BMP Bataan 2'!$H$63="n/a","na",IF('BMP Bataan 2'!$H$63="Active","✓","x")) -> na | BJ6: =IF('BMP Bataan 2'!$H$64="n/a","na",IF('BMP Bataan 2'!$H$64="Active","✓","x")) -> ✓ | BK6: =IF('BMP Bataan 2'!$H$65="n/a","na",IF('BMP Bataan 2'!$H$65="Active","✓","x")) -> na | BL6: =IF('BMP Bataan 2'!$H$66="n/a","na",IF('BMP Bataan 2'!$H$66="Active","✓","x")) -> ✓ | BM6: =IF('BMP Bataan 2'!$H$67="n/a","na",IF('BMP Bataan 2'!$H$67="Active","✓","x")) -> ✓ | BN6: =IF('BMP Bataan 2'!$H$68="n/a","na",IF('BMP Bataan 2'!$H$68="Active","✓","x")) -> x | BP6: =COUNTIF(D6:BN6,"*")-COUNTIF(D6:BN6,"NA") -> 26 | BQ6: =COUNTIF(D6:BN6,"✓") -> 23 | BR6: =IFERROR(BQ6/BP6,0) -> 0.88461538
B7: North Luzon | C7: BMP Bulacan | D7: =IF('BMP Bulacan'!$H$6="n/a","na",IF('BMP Bulacan'!$H$6="Active","✓","x")) -> ✓ | E7: =IF('BMP Bulacan'!$H$7="n/a","na",IF('BMP Bulacan'!$H$7="Active","✓","x")) -> ✓ | F7: =IF('BMP Bulacan'!$H$8="n/a","na",IF('BMP Bulacan'!$H$8="Active","✓","x")) -> na | G7: =IF('BMP Bulacan'!$H$9="n/a","na",IF('BMP Bulacan'!$H$9="Active","✓","x")) -> na | H7: =IF('BMP Bulacan'!$H$10="n/a","na",IF('BMP Bulacan'!$H$10="Active","✓","x")) -> na | I7: =IF('BMP Bulacan'!$H$11="n/a","na",IF('BMP Bulacan'!$H$11="Active","✓","x")) -> na | J7: =IF('BMP Bulacan'!$H$12="n/a","na",IF('BMP Bulacan'!$H$12="Active","✓","x")) -> ✓ | K7: =IF('BMP Bulacan'!$H$13="n/a","na",IF('BMP Bulacan'!$H$13="Active","✓","x")) -> ✓ | L7: =IF('BMP Bulacan'!$H$14="n/a","na",IF('BMP Bulacan'!$H$14="Active","✓","x")) -> ✓ | M7: =IF('BMP Bulacan'!$H$15="n/a","na",IF('BMP Bulacan'!$H$15="Active","✓","x")) -> ✓ | N7: =IF('BMP Bulacan'!$H$16="n/a","na",IF('BMP Bulacan'!$H$16="Active","✓","x")) -> ✓ | O7: =IF('BMP Bulacan'!$H$17="n/a","na",IF('BMP Bulacan'!$H$17="Active","✓","x")) -> na | P7: =IF('BMP Bulacan'!$H$18="n/a","na",IF('BMP Bulacan'!$H$18="Active","✓","x")) -> ✓ | Q7: =IF('BMP Bulacan'!$H$19="n/a","na",IF('BMP Bulacan'!$H$19="Active","✓","x")) -> ✓ | R7: =IF('BMP Bulacan'!$H$20="n/a","na",IF('BMP Bulacan'!$H$20="Active","✓","x")) -> ✓ | S7: =IF('BMP Bulacan'!$H$21="n/a","na",IF('BMP Bulacan'!$H$21="Active","✓","x")) -> ✓ | T7: =IF('BMP Bulacan'!$H$22="n/a","na",IF('BMP Bulacan'!$H$22="Active","✓","x")) -> ✓ | U7: =IF('BMP Bulacan'!$H$23="n/a","na",IF('BMP Bulacan'!$H$23="Active","✓","x")) -> ✓ | V7: =IF('BMP Bulacan'!$H$24="n/a","na",IF('BMP Bulacan'!$H$24="Active","✓","x")) -> na | W7: =IF('BMP Bulacan'!$H$25="n/a","na",IF('BMP Bulacan'!$H$25="Active","✓","x")) -> ✓ | X7: =IF('BMP Bulacan'!$H$26="n/a","na",IF('BMP Bulacan'!$H$26="Active","✓","x")) -> ✓ | Y7: =IF('BMP Bulacan'!$H$27="n/a","na",IF('BMP Bulacan'!$H$27="Active","✓","x")) -> na | Z7: =IF('BMP Bulacan'!$H$28="n/a","na",IF('BMP Bulacan'!$H$28="Active","✓","x")) -> na | AA7: =IF('BMP Bulacan'!$H$29="n/a","na",IF('BMP Bulacan'!$H$29="Active","✓","x")) -> ✓ | AB7: =IF('BMP Bulacan'!$H$30="n/a","na",IF('BMP Bulacan'!$H$30="Active","✓","x")) -> na | AC7: =IF('BMP Bulacan'!$H$31="n/a","na",IF('BMP Bulacan'!$H$31="Active","✓","x")) -> na | AD7: =IF('BMP Bulacan'!$H$32="n/a","na",IF('BMP Bulacan'!$H$32="Active","✓","x")) -> na | AE7: =IF('BMP Bulacan'!$H$33="n/a","na",IF('BMP Bulacan'!$H$33="Active","✓","x")) -> ✓ | AF7: =IF('BMP Bulacan'!$H$34="n/a","na",IF('BMP Bulacan'!$H$34="Active","✓","x")) -> ✓ | AG7: =IF('BMP Bulacan'!$H$35="n/a","na",IF('BMP Bulacan'!$H$35="Active","✓","x")) -> ✓ | AH7: =IF('BMP Bulacan'!$H$36="n/a","na",IF('BMP Bulacan'!$H$36="Active","✓","x")) -> na | AI7: =IF('BMP Bulacan'!$H$37="n/a","na",IF('BMP Bulacan'!$H$37="Active","✓","x")) -> na | AJ7: =IF('BMP Bulacan'!$H$38="n/a","na",IF('BMP Bulacan'!$H$38="Active","✓","x")) -> na | AK7: =IF('BMP Bulacan'!$H$39="n/a","na",IF('BMP Bulacan'!$H$39="Active","✓","x")) -> na | AL7: =IF('BMP Bulacan'!$H$40="n/a","na",IF('BMP Bulacan'!$H$40="Active","✓","x")) -> na | AM7: =IF('BMP Bulacan'!$H$41="n/a","na",IF('BMP Bulacan'!$H$41="Active","✓","x")) -> na | AN7: =IF('BMP Bulacan'!$H$42="n/a","na",IF('BMP Bulacan'!$H$42="Active","✓","x")) -> ✓ | AO7: =IF('BMP Bulacan'!$H$43="n/a","na",IF('BMP Bulacan'!$H$43="Active","✓","x")) -> na | AP7: =IF('BMP Bulacan'!$H$44="n/a","na",IF('BMP Bulacan'!$H$44="Active","✓","x")) -> na | AQ7: =IF('BMP Bulacan'!$H$45="n/a","na",IF('BMP Bulacan'!$H$45="Active","✓","x")) -> na | AR7: =IF('BMP Bulacan'!$H$46="n/a","na",IF('BMP Bulacan'!$H$46="Active","✓","x")) -> na | AS7: =IF('BMP Bulacan'!$H$47="n/a","na",IF('BMP Bulacan'!$H$47="Active","✓","x")) -> na | AT7: =IF('BMP Bulacan'!$H$48="n/a","na",IF('BMP Bulacan'!$H$48="Active","✓","x")) -> x | AU7: =IF('BMP Bulacan'!$H$49="n/a","na",IF('BMP Bulacan'!$H$49="Active","✓","x")) -> na | AV7: =IF('BMP Bulacan'!$H$50="n/a","na",IF('BMP Bulacan'!$H$50="Active","✓","x")) -> na | AW7: =IF('BMP Bulacan'!$H$51="n/a","na",IF('BMP Bulacan'!$H$51="Active","✓","x")) -> na | AX7: =IF('BMP Bulacan'!$H$52="n/a","na",IF('BMP Bulacan'!$H$52="Active","✓","x")) -> na | AY7: =IF('BMP Bulacan'!$H$53="n/a","na",IF('BMP Bulacan'!$H$53="Active","✓","x")) -> na | AZ7: =IF('BMP Bulacan'!$H$54="n/a","na",IF('BMP Bulacan'!$H$54="Active","✓","x")) -> na | BA7: =IF('BMP Bulacan'!$H$55="n/a","na",IF('BMP Bulacan'!$H$55="Active","✓","x")) -> na | BB7: =IF('BMP Bulacan'!$H$56="n/a","na",IF('BMP Bulacan'!$H$56="Active","✓","x")) -> na | BC7: =IF('BMP Bulacan'!$H$57="n/a","na",IF('BMP Bulacan'!$H$57="Active","✓","x")) -> na | BD7: =IF('BMP Bulacan'!$H$58="n/a","na",IF('BMP Bulacan'!$H$58="Active","✓","x")) -> na | BE7: =IF('BMP Bulacan'!$H$59="n/a","na",IF('BMP Bulacan'!$H$59="Active","✓","x")) -> na | BF7: =IF('BMP Bulacan'!$H$60="n/a","na",IF('BMP Bulacan'!$H$60="Active","✓","x")) -> na | BG7: =IF('BMP Bulacan'!$H$61="n/a","na",IF('BMP Bulacan'!$H$61="Active","✓","x")) -> na | BH7: =IF('BMP Bulacan'!$H$62="n/a","na",IF('BMP Bulacan'!$H$62="Active","✓","x")) -> na | BI7: =IF('BMP Bulacan'!$H$63="n/a","na",IF('BMP Bulacan'!$H$63="Active","✓","x")) -> na | BJ7: =IF('BMP Bulacan'!$H$64="n/a","na",IF('BMP Bulacan'!$H$64="Active","✓","x")) -> ✓ | BK7: =IF('BMP Bulacan'!$H$65="n/a","na",IF('BMP Bulacan'!$H$65="Active","✓","x")) -> na | BL7: =IF('BMP Bulacan'!$H$66="n/a","na",IF('BMP Bulacan'!$H$66="Active","✓","x")) -> ✓ | BM7: =IF('BMP Bulacan'!$H$67="n/a","na",IF('BMP Bulacan'!$H$67="Active","✓","x")) -> ✓ | BN7: =IF('BMP Bulacan'!$H$68="n/a","na",IF('BMP Bulacan'!$H$68="Active","✓","x")) -> ✓ | BP7: =COUNTIF(D7:BN7,"*")-COUNTIF(D7:BN7,"NA") -> 25 | BQ7: =COUNTIF(D7:BN7,"✓") -> 24 | BR7: =IFERROR(BQ7/BP7,0) -> 0.96
B8: North Luzon | C8: BMP Tarlac | D8: =IF('BMP Tarlac'!$H$6="n/a","na",IF('BMP Tarlac'!$H$6="Active","✓","x")) -> ✓ | E8: =IF('BMP Tarlac'!$H$7="n/a","na",IF('BMP Tarlac'!$H$7="Active","✓","x")) -> ✓ | F8: =IF('BMP Tarlac'!$H$8="n/a","na",IF('BMP Tarlac'!$H$8="Active","✓","x")) -> ✓ | G8: =IF('BMP Tarlac'!$H$9="n/a","na",IF('BMP Tarlac'!$H$9="Active","✓","x")) -> na | H8: =IF('BMP Tarlac'!$H$10="n/a","na",IF('BMP Tarlac'!$H$10="Active","✓","x")) -> na | I8: =IF('BMP Tarlac'!$H$11="n/a","na",IF('BMP Tarlac'!$H$11="Active","✓","x")) -> na | J8: =IF('BMP Tarlac'!$H$12="n/a","na",IF('BMP Tarlac'!$H$12="Active","✓","x")) -> ✓ | K8: =IF('BMP Tarlac'!$H$13="n/a","na",IF('BMP Tarlac'!$H$13="Active","✓","x")) -> ✓ | L8: =IF('BMP Tarlac'!$H$14="n/a","na",IF('BMP Tarlac'!$H$14="Active","✓","x")) -> ✓ | M8: =IF('BMP Tarlac'!$H$15="n/a","na",IF('BMP Tarlac'!$H$15="Active","✓","x")) -> ✓ | N8: =IF('BMP Tarlac'!$H$16="n/a","na",IF('BMP Tarlac'!$H$16="Active","✓","x")) -> ✓ | O8: =IF('BMP Tarlac'!$H$17="n/a","na",IF('BMP Tarlac'!$H$17="Active","✓","x")) -> na | P8: =IF('BMP Tarlac'!$H$18="n/a","na",IF('BMP Tarlac'!$H$18="Active","✓","x")) -> ✓ | Q8: =IF('BMP Tarlac'!$H$19="n/a","na",IF('BMP Tarlac'!$H$19="Active","✓","x")) -> na | R8: =IF('BMP Tarlac'!$H$20="n/a","na",IF('BMP Tarlac'!$H$20="Active","✓","x")) -> ✓ | S8: =IF('BMP Tarlac'!$H$21="n/a","na",IF('BMP Tarlac'!$H$21="Active","✓","x")) -> ✓ | T8: =IF('BMP Tarlac'!$H$22="n/a","na",IF('BMP Tarlac'!$H$22="Active","✓","x")) -> x | U8: =IF('BMP Tarlac'!$H$23="n/a","na",IF('BMP Tarlac'!$H$23="Active","✓","x")) -> ✓ | V8: =IF('BMP Tarlac'!$H$24="n/a","na",IF('BMP Tarlac'!$H$24="Active","✓","x")) -> na | W8: =IF('BMP Tarlac'!$H$25="n/a","na",IF('BMP Tarlac'!$H$25="Active","✓","x")) -> ✓ | X8: =IF('BMP Tarlac'!$H$26="n/a","na",IF('BMP Tarlac'!$H$26="Active","✓","x")) -> ✓ | Y8: =IF('BMP Tarlac'!$H$27="n/a","na",IF('BMP Tarlac'!$H$27="Active","✓","x")) -> na | Z8: =IF('BMP Tarlac'!$H$28="n/a","na",IF('BMP Tarlac'!$H$28="Active","✓","x")) -> na | AA8: =IF('BMP Tarlac'!$H$29="n/a","na",IF('BMP Tarlac'!$H$29="Active","✓","x")) -> ✓ | AB8: =IF('BMP Tarlac'!$H$30="n/a","na",IF('BMP Tarlac'!$H$30="Active","✓","x")) -> na | AC8: =IF('BMP Tarlac'!$H$31="n/a","na",IF('BMP Tarlac'!$H$31="Active","✓","x")) -> na | AD8: =IF('BMP Tarlac'!$H$32="n/a","na",IF('BMP Tarlac'!$H$32="Active","✓","x")) -> na | AE8: =IF('BMP Tarlac'!$H$33="n/a","na",IF('BMP Tarlac'!$H$33="Active","✓","x")) -> ✓ | AF8: =IF('BMP Tarlac'!$H$34="n/a","na",IF('BMP Tarlac'!$H$34="Active","✓","x")) -> ✓ | AG8: =IF('BMP Tarlac'!$H$35="n/a","na",IF('BMP Tarlac'!$H$35="Active","✓","x")) -> na | AH8: =IF('BMP Tarlac'!$H$36="n/a","na",IF('BMP Tarlac'!$H$36="Active","✓","x")) -> na | AI8: =IF('BMP Tarlac'!$H$37="n/a","na",IF('BMP Tarlac'!$H$37="Active","✓","x")) -> na | AJ8: =IF('BMP Tarlac'!$H$38="n/a","na",IF('BMP Tarlac'!$H$38="Active","✓","x")) -> ✓ | AK8: =IF('BMP Tarlac'!$H$39="n/a","na",IF('BMP Tarlac'!$H$39="Active","✓","x")) -> na | AL8: =IF('BMP Tarlac'!$H$40="n/a","na",IF('BMP Tarlac'!$H$40="Active","✓","x")) -> na | AM8: =IF('BMP Tarlac'!$H$41="n/a","na",IF('BMP Tarlac'!$H$41="Active","✓","x")) -> na | AN8: =IF('BMP Tarlac'!$H$42="n/a","na",IF('BMP Tarlac'!$H$42="Active","✓","x")) -> ✓ | AO8: =IF('BMP Tarlac'!$H$43="n/a","na",IF('BMP Tarlac'!$H$43="Active","✓","x")) -> na | AP8: =IF('BMP Tarlac'!$H$44="n/a","na",IF('BMP Tarlac'!$H$44="Active","✓","x")) -> na | AQ8: =IF('BMP Tarlac'!$H$45="n/a","na",IF('BMP Tarlac'!$H$45="Active","✓","x")) -> na | AR8: =IF('BMP Tarlac'!$H$46="n/a","na",IF('BMP Tarlac'!$H$46="Active","✓","x")) -> na | AS8: =IF('BMP Tarlac'!$H$47="n/a","na",IF('BMP Tarlac'!$H$47="Active","✓","x")) -> na | AT8: =IF('BMP Tarlac'!$H$48="n/a","na",IF('BMP Tarlac'!$H$48="Active","✓","x")) -> ✓ | AU8: =IF('BMP Tarlac'!$H$49="n/a","na",IF('BMP Tarlac'!$H$49="Active","✓","x")) -> na | AV8: =IF('BMP Tarlac'!$H$50="n/a","na",IF('BMP Tarlac'!$H$50="Active","✓","x")) -> na | AW8: =IF('BMP Tarlac'!$H$51="n/a","na",IF('BMP Tarlac'!$H$51="Active","✓","x")) -> na | AX8: =IF('BMP Tarlac'!$H$52="n/a","na",IF('BMP Tarlac'!$H$52="Active","✓","x")) -> na | AY8: =IF('BMP Tarlac'!$H$53="n/a","na",IF('BMP Tarlac'!$H$53="Active","✓","x")) -> na | AZ8: =IF('BMP Tarlac'!$H$54="n/a","na",IF('BMP Tarlac'!$H$54="Active","✓","x")) -> na | BA8: =IF('BMP Tarlac'!$H$55="n/a","na",IF('BMP Tarlac'!$H$55="Active","✓","x")) -> na | BB8: =IF('BMP Tarlac'!$H$56="n/a","na",IF('BMP Tarlac'!$H$56="Active","✓","x")) -> na | BC8: =IF('BMP Tarlac'!$H$57="n/a","na",IF('BMP Tarlac'!$H$57="Active","✓","x")) -> na | BD8: =IF('BMP Tarlac'!$H$58="n/a","na",IF('BMP Tarlac'!$H$58="Active","✓","x")) -> na | BE8: =IF('BMP Tarlac'!$H$59="n/a","na",IF('BMP Tarlac'!$H$59="Active","✓","x")) -> na | BF8: =IF('BMP Tarlac'!$H$60="n/a","na",IF('BMP Tarlac'!$H$60="Active","✓","x")) -> na | BG8: =IF('BMP Tarlac'!$H$61="n/a","na",IF('BMP Tarlac'!$H$61="Active","✓","x")) -> na | BH8: =IF('BMP Tarlac'!$H$62="n/a","na",IF('BMP Tarlac'!$H$62="Active","✓","x")) -> na | BI8: =IF('BMP Tarlac'!$H$63="n/a","na",IF('BMP Tarlac'!$H$63="Active","✓","x")) -> na | BJ8: =IF('BMP Tarlac'!$H$64="n/a","na",IF('BMP Tarlac'!$H$64="Active","✓","x")) -> na | BK8: =IF('BMP Tarlac'!$H$65="n/a","na",IF('BMP Tarlac'!$H$65="Active","✓","x")) -> na | BL8: =IF('BMP Tarlac'!$H$66="n/a","na",IF('BMP Tarlac'!$H$66="Active","✓","x")) -> ✓ | BM8: =IF('BMP Tarlac'!$H$67="n/a","na",IF('BMP Tarlac'!$H$67="Active","✓","x")) -> na | BN8: =IF('BMP Tarlac'!$H$68="n/a","na",IF('BMP Tarlac'!$H$68="Active","✓","x")) -> ✓ | BP8: =COUNTIF(D8:BN8,"*")-COUNTIF(D8:BN8,"NA") -> 23 | BQ8: =COUNTIF(D8:BN8,"✓") -> 22 | BR8: =IFERROR(BQ8/BP8,0) -> 0.95652174
B9: North Luzon | C9: MPF Bataan | D9: =IF('MPF Bataan'!$H$6="n/a","na",IF('MPF Bataan'!$H$6="Active","✓","x")) -> ✓ | E9: =IF('MPF Bataan'!$H$7="n/a","na",IF('MPF Bataan'!$H$7="Active","✓","x")) -> ✓ | F9: =IF('MPF Bataan'!$H$8="n/a","na",IF('MPF Bataan'!$H$8="Active","✓","x")) -> ✓ | G9: =IF('MPF Bataan'!$H$9="n/a","na",IF('MPF Bataan'!$H$9="Active","✓","x")) -> na | H9: =IF('MPF Bataan'!$H$10="n/a","na",IF('MPF Bataan'!$H$10="Active","✓","x")) -> na | I9: =IF('MPF Bataan'!$H$11="n/a","na",IF('MPF Bataan'!$H$11="Active","✓","x")) -> na | J9: =IF('MPF Bataan'!$H$12="n/a","na",IF('MPF Bataan'!$H$12="Active","✓","x")) -> ✓ | K9: =IF('MPF Bataan'!$H$13="n/a","na",IF('MPF Bataan'!$H$13="Active","✓","x")) -> ✓ | L9: =IF('MPF Bataan'!$H$14="n/a","na",IF('MPF Bataan'!$H$14="Active","✓","x")) -> na | M9: =IF('MPF Bataan'!$H$15="n/a","na",IF('MPF Bataan'!$H$15="Active","✓","x")) -> na | N9: =IF('MPF Bataan'!$H$16="n/a","na",IF('MPF Bataan'!$H$16="Active","✓","x")) -> ✓ | O9: =IF('MPF Bataan'!$H$17="n/a","na",IF('MPF Bataan'!$H$17="Active","✓","x")) -> na | P9: =IF('MPF Bataan'!$H$18="n/a","na",IF('MPF Bataan'!$H$18="Active","✓","x")) -> na | Q9: =IF('MPF Bataan'!$H$19="n/a","na",IF('MPF Bataan'!$H$19="Active","✓","x")) -> na | R9: =IF('MPF Bataan'!$H$20="n/a","na",IF('MPF Bataan'!$H$20="Active","✓","x")) -> na | S9: =IF('MPF Bataan'!$H$21="n/a","na",IF('MPF Bataan'!$H$21="Active","✓","x")) -> x | T9: =IF('MPF Bataan'!$H$22="n/a","na",IF('MPF Bataan'!$H$22="Active","✓","x")) -> x | U9: =IF('MPF Bataan'!$H$23="n/a","na",IF('MPF Bataan'!$H$23="Active","✓","x")) -> ✓ | V9: =IF('MPF Bataan'!$H$24="n/a","na",IF('MPF Bataan'!$H$24="Active","✓","x")) -> na | W9: =IF('MPF Bataan'!$H$25="n/a","na",IF('MPF Bataan'!$H$25="Active","✓","x")) -> ✓ | X9: =IF('MPF Bataan'!$H$26="n/a","na",IF('MPF Bataan'!$H$26="Active","✓","x")) -> ✓ | Y9: =IF('MPF Bataan'!$H$27="n/a","na",IF('MPF Bataan'!$H$27="Active","✓","x")) -> na | Z9: =IF('MPF Bataan'!$H$28="n/a","na",IF('MPF Bataan'!$H$28="Active","✓","x")) -> na | AA9: =IF('MPF Bataan'!$H$29="n/a","na",IF('MPF Bataan'!$H$29="Active","✓","x")) -> ✓ | AB9: =IF('MPF Bataan'!$H$30="n/a","na",IF('MPF Bataan'!$H$30="Active","✓","x")) -> na | AC9: =IF('MPF Bataan'!$H$31="n/a","na",IF('MPF Bataan'!$H$31="Active","✓","x")) -> na | AD9: =IF('MPF Bataan'!$H$32="n/a","na",IF('MPF Bataan'!$H$32="Active","✓","x")) -> na | AE9: =IF('MPF Bataan'!$H$33="n/a","na",IF('MPF Bataan'!$H$33="Active","✓","x")) -> ✓ | AF9: =IF('MPF Bataan'!$H$34="n/a","na",IF('MPF Bataan'!$H$34="Active","✓","x")) -> ✓ | AG9: =IF('MPF Bataan'!$H$35="n/a","na",IF('MPF Bataan'!$H$35="Active","✓","x")) -> na | AH9: =IF('MPF Bataan'!$H$36="n/a","na",IF('MPF Bataan'!$H$36="Active","✓","x")) -> na | AI9: =IF('MPF Bataan'!$H$37="n/a","na",IF('MPF Bataan'!$H$37="Active","✓","x")) -> na | AJ9: =IF('MPF Bataan'!$H$38="n/a","na",IF('MPF Bataan'!$H$38="Active","✓","x")) -> na | AK9: =IF('MPF Bataan'!$H$39="n/a","na",IF('MPF Bataan'!$H$39="Active","✓","x")) -> na | AL9: =IF('MPF Bataan'!$H$40="n/a","na",IF('MPF Bataan'!$H$40="Active","✓","x")) -> na | AM9: =IF('MPF Bataan'!$H$41="n/a","na",IF('MPF Bataan'!$H$41="Active","✓","x")) -> na | AN9: =IF('MPF Bataan'!$H$42="n/a","na",IF('MPF Bataan'!$H$42="Active","✓","x")) -> na | AO9: =IF('MPF Bataan'!$H$43="n/a","na",IF('MPF Bataan'!$H$43="Active","✓","x")) -> na | AP9: =IF('MPF Bataan'!$H$44="n/a","na",IF('MPF Bataan'!$H$44="Active","✓","x")) -> na | AQ9: =IF('MPF Bataan'!$H$45="n/a","na",IF('MPF Bataan'!$H$45="Active","✓","x")) -> na | AR9: =IF('MPF Bataan'!$H$46="n/a","na",IF('MPF Bataan'!$H$46="Active","✓","x")) -> na | AS9: =IF('MPF Bataan'!$H$47="n/a","na",IF('MPF Bataan'!$H$47="Active","✓","x")) -> na | AT9: =IF('MPF Bataan'!$H$48="n/a","na",IF('MPF Bataan'!$H$48="Active","✓","x")) -> na | AU9: =IF('MPF Bataan'!$H$49="n/a","na",IF('MPF Bataan'!$H$49="Active","✓","x")) -> na | AV9: =IF('MPF Bataan'!$H$50="n/a","na",IF('MPF Bataan'!$H$50="Active","✓","x")) -> ✓ | AW9: =IF('MPF Bataan'!$H$51="n/a","na",IF('MPF Bataan'!$H$51="Active","✓","x")) -> ✓ | AX9: =IF('MPF Bataan'!$H$52="n/a","na",IF('MPF Bataan'!$H$52="Active","✓","x")) -> na | AY9: =IF('MPF Bataan'!$H$53="n/a","na",IF('MPF Bataan'!$H$53="Active","✓","x")) -> na | AZ9: =IF('MPF Bataan'!$H$54="n/a","na",IF('MPF Bataan'!$H$54="Active","✓","x")) -> na | BA9: =IF('MPF Bataan'!$H$55="n/a","na",IF('MPF Bataan'!$H$55="Active","✓","x")) -> na | BB9: =IF('MPF Bataan'!$H$56="n/a","na",IF('MPF Bataan'!$H$56="Active","✓","x")) -> na | BC9: =IF('MPF Bataan'!$H$57="n/a","na",IF('MPF Bataan'!$H$57="Active","✓","x")) -> na | BD9: =IF('MPF Bataan'!$H$58="n/a","na",IF('MPF Bataan'!$H$58="Active","✓","x")) -> na | BE9: =IF('MPF Bataan'!$H$59="n/a","na",IF('MPF Bataan'!$H$59="Active","✓","x")) -> na | BF9: =IF('MPF Bataan'!$H$60="n/a","na",IF('MPF Bataan'!$H$60="Active","✓","x")) -> na | BG9: =IF('MPF Bataan'!$H$61="n/a","na",IF('MPF Bataan'!$H$61="Active","✓","x")) -> na | BH9: =IF('MPF Bataan'!$H$62="n/a","na",IF('MPF Bataan'!$H$62="Active","✓","x")) -> na | BI9: =IF('MPF Bataan'!$H$63="n/a","na",IF('MPF Bataan'!$H$63="Active","✓","x")) -> na | BJ9: =IF('MPF Bataan'!$H$64="n/a","na",IF('MPF Bataan'!$H$64="Active","✓","x")) -> na | BK9: =IF('MPF Bataan'!$H$65="n/a","na",IF('MPF Bataan'!$H$65="Active","✓","x")) -> ✓ | BL9: =IF('MPF Bataan'!$H$66="n/a","na",IF('MPF Bataan'!$H$66="Active","✓","x")) -> na | BM9: =IF('MPF Bataan'!$H$67="n/a","na",IF('MPF Bataan'!$H$67="Active","✓","x")) -> na | BN9: =IF('MPF Bataan'!$H$68="n/a","na",IF('MPF Bataan'!$H$68="Active","✓","x")) -> na | BP9: =COUNTIF(D9:BN9,"*")-COUNTIF(D9:BN9,"NA") -> 17 | BQ9: =COUNTIF(D9:BN9,"✓") -> 15 | BR9: =IFERROR(BQ9/BP9,0) -> 0.88235294
B10: North Luzon | C10: MPH Bataan | D10: =IF('MPH Bataan'!$H$6="n/a","na",IF('MPH Bataan'!$H$6="Active","✓","x")) -> ✓ | E10: =IF('MPH Bataan'!$H$7="n/a","na",IF('MPH Bataan'!$H$7="Active","✓","x")) -> ✓ | F10: =IF('MPH Bataan'!$H$8="n/a","na",IF('MPH Bataan'!$H$8="Active","✓","x")) -> ✓ | G10: =IF('MPH Bataan'!$H$9="n/a","na",IF('MPH Bataan'!$H$9="Active","✓","x")) -> na | H10: =IF('MPH Bataan'!$H$10="n/a","na",IF('MPH Bataan'!$H$10="Active","✓","x")) -> na | I10: =IF('MPH Bataan'!$H$11="n/a","na",IF('MPH Bataan'!$H$11="Active","✓","x")) -> na | J10: =IF('MPH Bataan'!$H$12="n/a","na",IF('MPH Bataan'!$H$12="Active","✓","x")) -> ✓ | K10: =IF('MPH Bataan'!$H$13="n/a","na",IF('MPH Bataan'!$H$13="Active","✓","x")) -> x | L10: =IF('MPH Bataan'!$H$14="n/a","na",IF('MPH Bataan'!$H$14="Active","✓","x")) -> na | M10: =IF('MPH Bataan'!$H$15="n/a","na",IF('MPH Bataan'!$H$15="Active","✓","x")) -> ✓ | N10: =IF('MPH Bataan'!$H$16="n/a","na",IF('MPH Bataan'!$H$16="Active","✓","x")) -> ✓ | O10: =IF('MPH Bataan'!$H$17="n/a","na",IF('MPH Bataan'!$H$17="Active","✓","x")) -> na | P10: =IF('MPH Bataan'!$H$18="n/a","na",IF('MPH Bataan'!$H$18="Active","✓","x")) -> na | Q10: =IF('MPH Bataan'!$H$19="n/a","na",IF('MPH Bataan'!$H$19="Active","✓","x")) -> na | R10: =IF('MPH Bataan'!$H$20="n/a","na",IF('MPH Bataan'!$H$20="Active","✓","x")) -> na | S10: =IF('MPH Bataan'!$H$21="n/a","na",IF('MPH Bataan'!$H$21="Active","✓","x")) -> x | T10: =IF('MPH Bataan'!$H$22="n/a","na",IF('MPH Bataan'!$H$22="Active","✓","x")) -> x | U10: =IF('MPH Bataan'!$H$23="n/a","na",IF('MPH Bataan'!$H$23="Active","✓","x")) -> ✓ | V10: =IF('MPH Bataan'!$H$24="n/a","na",IF('MPH Bataan'!$H$24="Active","✓","x")) -> na | W10: =IF('MPH Bataan'!$H$25="n/a","na",IF('MPH Bataan'!$H$25="Active","✓","x")) -> ✓ | X10: =IF('MPH Bataan'!$H$26="n/a","na",IF('MPH Bataan'!$H$26="Active","✓","x")) -> ✓ | Y10: =IF('MPH Bataan'!$H$27="n/a","na",IF('MPH Bataan'!$H$27="Active","✓","x")) -> na | Z10: =IF('MPH Bataan'!$H$28="n/a","na",IF('MPH Bataan'!$H$28="Active","✓","x")) -> na | AA10: =IF('MPH Bataan'!$H$29="n/a","na",IF('MPH Bataan'!$H$29="Active","✓","x")) -> ✓ | AB10: =IF('MPH Bataan'!$H$30="n/a","na",IF('MPH Bataan'!$H$30="Active","✓","x")) -> na | AC10: =IF('MPH Bataan'!$H$31="n/a","na",IF('MPH Bataan'!$H$31="Active","✓","x")) -> na | AD10: =IF('MPH Bataan'!$H$32="n/a","na",IF('MPH Bataan'!$H$32="Active","✓","x")) -> na | AE10: =IF('MPH Bataan'!$H$33="n/a","na",IF('MPH Bataan'!$H$33="Active","✓","x")) -> ✓ | AF10: =IF('MPH Bataan'!$H$34="n/a","na",IF('MPH Bataan'!$H$34="Active","✓","x")) -> ✓ | AG10: =IF('MPH Bataan'!$H$35="n/a","na",IF('MPH Bataan'!$H$35="Active","✓","x")) -> na | AH10: =IF('MPH Bataan'!$H$36="n/a","na",IF('MPH Bataan'!$H$36="Active","✓","x")) -> na | AI10: =IF('MPH Bataan'!$H$37="n/a","na",IF('MPH Bataan'!$H$37="Active","✓","x")) -> na | AJ10: =IF('MPH Bataan'!$H$38="n/a","na",IF('MPH Bataan'!$H$38="Active","✓","x")) -> na | AK10: =IF('MPH Bataan'!$H$39="n/a","na",IF('MPH Bataan'!$H$39="Active","✓","x")) -> na | AL10: =IF('MPH Bataan'!$H$40="n/a","na",IF('MPH Bataan'!$H$40="Active","✓","x")) -> na | AM10: =IF('MPH Bataan'!$H$41="n/a","na",IF('MPH Bataan'!$H$41="Active","✓","x")) -> na | AN10: =IF('MPH Bataan'!$H$42="n/a","na",IF('MPH Bataan'!$H$42="Active","✓","x")) -> na | AO10: =IF('MPH Bataan'!$H$43="n/a","na",IF('MPH Bataan'!$H$43="Active","✓","x")) -> na | AP10: =IF('MPH Bataan'!$H$44="n/a","na",IF('MPH Bataan'!$H$44="Active","✓","x")) -> na | AQ10: =IF('MPH Bataan'!$H$45="n/a","na",IF('MPH Bataan'!$H$45="Active","✓","x")) -> na | AR10: =IF('MPH Bataan'!$H$46="n/a","na",IF('MPH Bataan'!$H$46="Active","✓","x")) -> na | AS10: =IF('MPH Bataan'!$H$47="n/a","na",IF('MPH Bataan'!$H$47="Active","✓","x")) -> na | AT10: =IF('MPH Bataan'!$H$48="n/a","na",IF('MPH Bataan'!$H$48="Active","✓","x")) -> na | AU10: =IF('MPH Bataan'!$H$49="n/a","na",IF('MPH Bataan'!$H$49="Active","✓","x")) -> ✓ | AV10: =IF('MPH Bataan'!$H$50="n/a","na",IF('MPH Bataan'!$H$50="Active","✓","x")) -> ✓ | AW10: =IF('MPH Bataan'!$H$51="n/a","na",IF('MPH Bataan'!$H$51="Active","✓","x")) -> ✓ | AX10: =IF('MPH Bataan'!$H$52="n/a","na",IF('MPH Bataan'!$H$52="Active","✓","x")) -> na | AY10: =IF('MPH Bataan'!$H$53="n/a","na",IF('MPH Bataan'!$H$53="Active","✓","x")) -> na | AZ10: =IF('MPH Bataan'!$H$54="n/a","na",IF('MPH Bataan'!$H$54="Active","✓","x")) -> na | BA10: =IF('MPH Bataan'!$H$55="n/a","na",IF('MPH Bataan'!$H$55="Active","✓","x")) -> na | BB10: =IF('MPH Bataan'!$H$56="n/a","na",IF('MPH Bataan'!$H$56="Active","✓","x")) -> na | BC10: =IF('MPH Bataan'!$H$57="n/a","na",IF('MPH Bataan'!$H$57="Active","✓","x")) -> na | BD10: =IF('MPH Bataan'!$H$58="n/a","na",IF('MPH Bataan'!$H$58="Active","✓","x")) -> na | BE10: =IF('MPH Bataan'!$H$59="n/a","na",IF('MPH Bataan'!$H$59="Active","✓","x")) -> na | BF10: =IF('MPH Bataan'!$H$60="n/a","na",IF('MPH Bataan'!$H$60="Active","✓","x")) -> na | BG10: =IF('MPH Bataan'!$H$61="n/a","na",IF('MPH Bataan'!$H$61="Active","✓","x")) -> na | BH10: =IF('MPH Bataan'!$H$62="n/a","na",IF('MPH Bataan'!$H$62="Active","✓","x")) -> na | BI10: =IF('MPH Bataan'!$H$63="n/a","na",IF('MPH Bataan'!$H$63="Active","✓","x")) -> na | BJ10: =IF('MPH Bataan'!$H$64="n/a","na",IF('MPH Bataan'!$H$64="Active","✓","x")) -> na | BK10: =IF('MPH Bataan'!$H$65="n/a","na",IF('MPH Bataan'!$H$65="Active","✓","x")) -> ✓ | BL10: =IF('MPH Bataan'!$H$66="n/a","na",IF('MPH Bataan'!$H$66="Active","✓","x")) -> na | BM10: =IF('MPH Bataan'!$H$67="n/a","na",IF('MPH Bataan'!$H$67="Active","✓","x")) -> na | BN10: =IF('MPH Bataan'!$H$68="n/a","na",IF('MPH Bataan'!$H$68="Active","✓","x")) -> na | BP10: =COUNTIF(D10:BN10,"*")-COUNTIF(D10:BN10,"NA") -> 19 | BQ10: =COUNTIF(D10:BN10,"✓") -> 16 | BR10: =IFERROR(BQ10/BP10,0) -> 0.84210526
B11: South Luzon | C11: BMP Batangas | D11: =IF('BMP Batangas'!$H$6="n/a","na",IF('BMP Batangas'!$H$6="Active","✓","x")) -> ✓ | E11: =IF('BMP Batangas'!$H$7="n/a","na",IF('BMP Batangas'!$H$7="Active","✓","x")) -> ✓ | F11: =IF('BMP Batangas'!$H$8="n/a","na",IF('BMP Batangas'!$H$8="Active","✓","x")) -> na | G11: =IF('BMP Batangas'!$H$9="n/a","na",IF('BMP Batangas'!$H$9="Active","✓","x")) -> na | H11: =IF('BMP Batangas'!$H$10="n/a","na",IF('BMP Batangas'!$H$10="Active","✓","x")) -> na | I11: =IF('BMP Batangas'!$H$11="n/a","na",IF('BMP Batangas'!$H$11="Active","✓","x")) -> x | J11: =IF('BMP Batangas'!$H$12="n/a","na",IF('BMP Batangas'!$H$12="Active","✓","x")) -> ✓ | K11: =IF('BMP Batangas'!$H$13="n/a","na",IF('BMP Batangas'!$H$13="Active","✓","x")) -> x | L11: =IF('BMP Batangas'!$H$14="n/a","na",IF('BMP Batangas'!$H$14="Active","✓","x")) -> ✓ | M11: =IF('BMP Batangas'!$H$15="n/a","na",IF('BMP Batangas'!$H$15="Active","✓","x")) -> ✓ | N11: =IF('BMP Batangas'!$H$16="n/a","na",IF('BMP Batangas'!$H$16="Active","✓","x")) -> x | O11: =IF('BMP Batangas'!$H$17="n/a","na",IF('BMP Batangas'!$H$17="Active","✓","x")) -> na | P11: =IF('BMP Batangas'!$H$18="n/a","na",IF('BMP Batangas'!$H$18="Active","✓","x")) -> x | Q11: =IF('BMP Batangas'!$H$19="n/a","na",IF('BMP Batangas'!$H$19="Active","✓","x")) -> x | R11: =IF('BMP Batangas'!$H$20="n/a","na",IF('BMP Batangas'!$H$20="Active","✓","x")) -> ✓ | S11: =IF('BMP Batangas'!$H$21="n/a","na",IF('BMP Batangas'!$H$21="Active","✓","x")) -> x | T11: =IF('BMP Batangas'!$H$22="n/a","na",IF('BMP Batangas'!$H$22="Active","✓","x")) -> ✓ | U11: =IF('BMP Batangas'!$H$23="n/a","na",IF('BMP Batangas'!$H$23="Active","✓","x")) -> ✓ | V11: =IF('BMP Batangas'!$H$24="n/a","na",IF('BMP Batangas'!$H$24="Active","✓","x")) -> na | W11: =IF('BMP Batangas'!$H$25="n/a","na",IF('BMP Batangas'!$H$25="Active","✓","x")) -> ✓ | X11: =IF('BMP Batangas'!$H$26="n/a","na",IF('BMP Batangas'!$H$26="Active","✓","x")) -> ✓ | Y11: =IF('BMP Batangas'!$H$27="n/a","na",IF('BMP Batangas'!$H$27="Active","✓","x")) -> ✓ | Z11: =IF('BMP Batangas'!$H$28="n/a","na",IF('BMP Batangas'!$H$28="Active","✓","x")) -> ✓ | AA11: =IF('BMP Batangas'!$H$29="n/a","na",IF('BMP Batangas'!$H$29="Active","✓","x")) -> ✓ | AB11: =IF('BMP Batangas'!$H$30="n/a","na",IF('BMP Batangas'!$H$30="Active","✓","x")) -> na | AC11: =IF('BMP Batangas'!$H$31="n/a","na",IF('BMP Batangas'!$H$31="Active","✓","x")) -> na | AD11: =IF('BMP Batangas'!$H$32="n/a","na",IF('BMP Batangas'!$H$32="Active","✓","x")) -> na | AE11: =IF('BMP Batangas'!$H$33="n/a","na",IF('BMP Batangas'!$H$33="Active","✓","x")) -> ✓ | AF11: =IF('BMP Batangas'!$H$34="n/a","na",IF('BMP Batangas'!$H$34="Active","✓","x")) -> ✓ | AG11: =IF('BMP Batangas'!$H$35="n/a","na",IF('BMP Batangas'!$H$35="Active","✓","x")) -> na | AH11: =IF('BMP Batangas'!$H$36="n/a","na",IF('BMP Batangas'!$H$36="Active","✓","x")) -> na | AI11: =IF('BMP Batangas'!$H$37="n/a","na",IF('BMP Batangas'!$H$37="Active","✓","x")) -> na | AJ11: =IF('BMP Batangas'!$H$38="n/a","na",IF('BMP Batangas'!$H$38="Active","✓","x")) -> ✓ | AK11: =IF('BMP Batangas'!$H$39="n/a","na",IF('BMP Batangas'!$H$39="Active","✓","x")) -> na | AL11: =IF('BMP Batangas'!$H$40="n/a","na",IF('BMP Batangas'!$H$40="Active","✓","x")) -> na | AM11: =IF('BMP Batangas'!$H$41="n/a","na",IF('BMP Batangas'!$H$41="Active","✓","x")) -> na | AN11: =IF('BMP Batangas'!$H$42="n/a","na",IF('BMP Batangas'!$H$42="Active","✓","x")) -> ✓ | AO11: =IF('BMP Batangas'!$H$43="n/a","na",IF('BMP Batangas'!$H$43="Active","✓","x")) -> na | AP11: =IF('BMP Batangas'!$H$44="n/a","na",IF('BMP Batangas'!$H$44="Active","✓","x")) -> na | AQ11: =IF('BMP Batangas'!$H$45="n/a","na",IF('BMP Batangas'!$H$45="Active","✓","x")) -> na | AR11: =IF('BMP Batangas'!$H$46="n/a","na",IF('BMP Batangas'!$H$46="Active","✓","x")) -> na | AS11: =IF('BMP Batangas'!$H$47="n/a","na",IF('BMP Batangas'!$H$47="Active","✓","x")) -> na | AT11: =IF('BMP Batangas'!$H$48="n/a","na",IF('BMP Batangas'!$H$48="Active","✓","x")) -> na | AU11: =IF('BMP Batangas'!$H$49="n/a","na",IF('BMP Batangas'!$H$49="Active","✓","x")) -> na | AV11: =IF('BMP Batangas'!$H$50="n/a","na",IF('BMP Batangas'!$H$50="Active","✓","x")) -> na | AW11: =IF('BMP Batangas'!$H$51="n/a","na",IF('BMP Batangas'!$H$51="Active","✓","x")) -> na | AX11: =IF('BMP Batangas'!$H$52="n/a","na",IF('BMP Batangas'!$H$52="Active","✓","x")) -> na | AY11: =IF('BMP Batangas'!$H$53="n/a","na",IF('BMP Batangas'!$H$53="Active","✓","x")) -> na | AZ11: =IF('BMP Batangas'!$H$54="n/a","na",IF('BMP Batangas'!$H$54="Active","✓","x")) -> na | BA11: =IF('BMP Batangas'!$H$55="n/a","na",IF('BMP Batangas'!$H$55="Active","✓","x")) -> na | BB11: =IF('BMP Batangas'!$H$56="n/a","na",IF('BMP Batangas'!$H$56="Active","✓","x")) -> na | BC11: =IF('BMP Batangas'!$H$57="n/a","na",IF('BMP Batangas'!$H$57="Active","✓","x")) -> x | BD11: =IF('BMP Batangas'!$H$58="n/a","na",IF('BMP Batangas'!$H$58="Active","✓","x")) -> na | BE11: =IF('BMP Batangas'!$H$59="n/a","na",IF('BMP Batangas'!$H$59="Active","✓","x")) -> na | BF11: =IF('BMP Batangas'!$H$60="n/a","na",IF('BMP Batangas'!$H$60="Active","✓","x")) -> na | BG11: =IF('BMP Batangas'!$H$61="n/a","na",IF('BMP Batangas'!$H$61="Active","✓","x")) -> na | BH11: =IF('BMP Batangas'!$H$62="n/a","na",IF('BMP Batangas'!$H$62="Active","✓","x")) -> na | BI11: =IF('BMP Batangas'!$H$63="n/a","na",IF('BMP Batangas'!$H$63="Active","✓","x")) -> na | BJ11: =IF('BMP Batangas'!$H$64="n/a","na",IF('BMP Batangas'!$H$64="Active","✓","x")) -> ✓ | BK11: =IF('BMP Batangas'!$H$65="n/a","na",IF('BMP Batangas'!$H$65="Active","✓","x")) -> na | BL11: =IF('BMP Batangas'!$H$66="n/a","na",IF('BMP Batangas'!$H$66="Active","✓","x")) -> ✓ | BM11: =IF('BMP Batangas'!$H$67="n/a","na",IF('BMP Batangas'!$H$67="Active","✓","x")) -> na | BN11: =IF('BMP Batangas'!$H$68="n/a","na",IF('BMP Batangas'!$H$68="Active","✓","x")) -> ✓ | BP11: =COUNTIF(D11:BN11,"*")-COUNTIF(D11:BN11,"NA") -> 27 | BQ11: =COUNTIF(D11:BN11,"✓") -> 20 | BR11: =IFERROR(BQ11/BP11,0) -> 0.74074074
